Demonstrate catching an Exception in a Constructor with Function try Blocks
